Workbook

Sheet All injections Liliom
B1: Grey header cells - fill automatically, can not be edited :::: Blue header cells - limited editibility, i.e. drop down list :::: Green header - freely editable comment fields | P1: Drop down lists can be changed on the Stats page!
A2: Animal State | D2: Animal IDs | N2: Virus injection details | X2: Surgery | AA2: Drop out | AC2: Notes
A3: Animal number | B3: State | C3: Category | D3: Arrival date | E3: Age (days) | F3: OGR number | G3: Box # | H3: Line | I3: Sex | J3: Project approval # | K3: Owner | L3: Project | M3: Project # check | N3: Injection Date | O3: Injection Pers. | P3: Vector 1 | Q3: Vector 2 | R3: Vector 3 | S3: Dill. | T3: Location | U3: Depth (µm) | V3: Quant. (nl) | W3: Note for the injection | X3: Surgery Date | Y3: Surgery Person | Z3: Note for surgery | AA3: Drop out Date | AB3: Drop out reason | AC3: Notes | AD3: Checkup | AE3: Checkup 2. | AF3: Checkup 3.
A4: Mouse_1 | B4: =IF((COUNTBLANK(AA4)=0),Stats!$E$7,IF((COUNTBLANK(N4)=0),IF((COUNTBLANK(X4)=0),IF((COUNTBLANK(AD4)=0),Stats!$E$6,Stats!$E$5),Stats!$E$4),"")) -> Death | C4: =IF(B4=Stats!$E$5,Stats!$E$11,"") | D4: 45712 | E4: =IFERROR(TODAY()-DATE(2000+MID(F4,SEARCH("-",F4,SEARCH("-",F4)+1)+1,2),MID(F4,SEARCH("-",F4,SEARCH("-",F4)+1)+3,2),MID(F4,SEARCH("-",F4,SEARCH("-",F4)+1)+5,2)),"") -> 499 | F4: 999-01-241001-11-046 | G4: o01/113 | H4: C57Bl/6J | I4: Male ♂ | J4: PE/EA/54-02/2019 | L4: Freely moving | M4: =COUNTA(D4)*COUNTA(F4)*COUNTA(J4)*COUNTA(L4) -> 1 | N4: 45687 | O4: S. Eszter | P4: AAV157 | Q4: AAV381 | S4: 1x, 1000 | T4: V1 | U4: -400 | V4: 400 | W4: left | X4: 45705 | Y4: PL - Popara Lídia | AA4: 45863 | AB4: humane endpoint | AC4: az a helyzet, hogy ezt az állatot megtaláltam a ketrecében, Forceos amúgy, szép expresszió, somák minden r.ben, jelek is vannak; allstaff\DATA\jasz.anna\VIP_dendrit\Measurements\VoltageSensors\FORCE\FORCE_checkup_202503212.mesc | AD4: 2025.02.28. fragments, N:\DATA\juhasz.gabor\Liliom\GCaMP6f_cage_113.mes | AF4: nem lehet befogni szm.ba
A5: Mouse_2 | B5: =IF((COUNTBLANK(AA5)=0),Stats!$E$7,IF((COUNTBLANK(N5)=0),IF((COUNTBLANK(X5)=0),IF((COUNTBLANK(AD5)=0),Stats!$E$6,Stats!$E$5),Stats!$E$4),"")) -> Death | C5: Behavior | D5: 45712 | E5: =IFERROR(TODAY()-DATE(2000+MID(F5,SEARCH("-",F5,SEARCH("-",F5)+1)+1,2),MID(F5,SEARCH("-",F5,SEARCH("-",F5)+1)+3,2),MID(F5,SEARCH("-",F5,SEARCH("-",F5)+1)+5,2)),"") -> 499 | F5: 999-01-241001-11-047 | G5: o01/113 | H5: C57Bl/6J | I5: Male ♂ | J5: PE/EA/54-02/2019 | K5: Wéber Katalin | L5: Moculus | M5: =COUNTA(D5)*COUNTA(F5)*COUNTA(J5)*COUNTA(L5) -> 1 | N5: 45687 | O5: S. Eszter | P5: AAV157 | Q5: AAV381 | S5: 1x, 1000 | T5: V1 | U5: -400 | V5: 400 | W5: right | X5: 45705 | Y5: PL - Popara Lídia | AA5: 46010 | AB5: humane endpoint | AC5: becsontosodott | AD5: 2025.02.28. fragments, N:\DATA\juhasz.gabor\Liliom\GCaMP6f_cage_113.mes
A6: Mouse_3 | B6: =IF((COUNTBLANK(AA6)=0),Stats!$E$7,IF((COUNTBLANK(N6)=0),IF((COUNTBLANK(X6)=0),IF((COUNTBLANK(AD6)=0),Stats!$E$6,Stats!$E$5),Stats!$E$4),"")) -> Death | C6: =IF(B6=Stats!$E$5,Stats!$E$11,"") | D6: 45712 | E6: =IFERROR(TODAY()-DATE(2000+MID(F6,SEARCH("-",F6,SEARCH("-",F6)+1)+1,2),MID(F6,SEARCH("-",F6,SEARCH("-",F6)+1)+3,2),MID(F6,SEARCH("-",F6,SEARCH("-",F6)+1)+5,2)),"") -> 499 | F6: 999-01-241001-11-048 | G6: o01/113 | H6: C57Bl/6J | I6: Male ♂ | J6: PE/EA/54-02/2019 | L6: Freely moving | M6: =COUNTA(D6)*COUNTA(F6)*COUNTA(J6)*COUNTA(L6) -> 1 | N6: 45687 | O6: S. Eszter | P6: AG54 | S6: 1x | T6: V1 | U6: -400 | V6: 400 | W6: left+righ | X6: 45705 | Y6: PL - Popara Lídia | AA6: 45863 | AB6: humane endpoint | AC6: Nagyon szép exp, somák, dendritek jól látszódnak, de talán túl expr, jelek nem nagyon vannak, somák -550nál; allstaff\DATA\jasz.anna\VIP_dendrit\Measurements\VoltageSensors\FORCE\FORCE_checkup_202503211.mesc | AD6: - | AF6: nem lehet befogni szm.ba
A7: Mouse_4 | B7: =IF((COUNTBLANK(AA7)=0),Stats!$E$7,IF((COUNTBLANK(N7)=0),IF((COUNTBLANK(X7)=0),IF((COUNTBLANK(AD7)=0),Stats!$E$6,Stats!$E$5),Stats!$E$4),"")) -> Death | C7: =IF(B7=Stats!$E$5,Stats!$E$11,"") | D7: 45712 | E7: =IFERROR(TODAY()-DATE(2000+MID(F7,SEARCH("-",F7,SEARCH("-",F7)+1)+1,2),MID(F7,SEARCH("-",F7,SEARCH("-",F7)+1)+3,2),MID(F7,SEARCH("-",F7,SEARCH("-",F7)+1)+5,2)),"") -> 499 | F7: 999-01-241001-11-049 | G7: o01/113 | H7: C57Bl/6J | I7: Male ♂ | J7: PE/EA/54-02/2019 | L7: Freely moving | M7: =COUNTA(D7)*COUNTA(F7)*COUNTA(J7)*COUNTA(L7) -> 1 | N7: 45687 | O7: S. Eszter | P7: AG54 | S7: 1x | T7: V1 | U7: -400 | V7: 400 | W7: no sign | X7: 45705 | Y7: PL - Popara Lídia | AA7: 45721 | AB7: anatomical test | AC7: IGAZÁBÓL EZ A HALOTT (m1 helyett, fülek alapján) | AF7: -
A8: Mouse_5 | B8: =IF((COUNTBLANK(AA8)=0),Stats!$E$7,IF((COUNTBLANK(N8)=0),IF((COUNTBLANK(X8)=0),IF((COUNTBLANK(AD8)=0),Stats!$E$6,Stats!$E$5),Stats!$E$4),"")) -> Death | C8: =IF(B8=Stats!$E$5,Stats!$E$11,"") | D8: 45712 | E8: =IFERROR(TODAY()-DATE(2000+MID(F8,SEARCH("-",F8,SEARCH("-",F8)+1)+1,2),MID(F8,SEARCH("-",F8,SEARCH("-",F8)+1)+3,2),MID(F8,SEARCH("-",F8,SEARCH("-",F8)+1)+5,2)),"") -> 463 | F8: 999-01-241106-11-090 | G8: o01/111 | H8: C57Bl/6J | I8: Male ♂ | J8: PE/EA/54-02/2019 | L8: Freely moving | M8: =COUNTA(D8)*COUNTA(F8)*COUNTA(J8)*COUNTA(L8) -> 1 | N8: 45688 | O8: S. Eszter | P8: AAV157 | Q8: AAV381 | S8: 1x, 1000 | T8: V1 | U8: -400 | V8: 400 | W8: left | X8: 45698 | Y8: PL - Popara Lídia | AA8: 45769 | AB8: death (sickness) | AC8: ez egy FORCEos egér, gyenge jel, de van néhány sejt, volt rajtuk AP is; allstaff\DATA\jasz.anna\VIP_dendrit\Measurements\VoltageSensors\FORCE\FORCE_checkup_202503212_2.mesc | AD8: 2025.02.28. fragments, N:\DATA\juhasz.gabor\Liliom\GCaMP6fCheckUpcage111all.mes | AE8: 2023-03-05 fragmented cells (n:\DATA\szalay.gergely\mes2025\check-up\2025-03-05_mous5_check-up.mes) | AF8: !!!
A9: Mouse_6 | B9: =IF((COUNTBLANK(AA9)=0),Stats!$E$7,IF((COUNTBLANK(N9)=0),IF((COUNTBLANK(X9)=0),IF((COUNTBLANK(AD9)=0),Stats!$E$6,Stats!$E$5),Stats!$E$4),"")) -> Death | C9: =IF(B9=Stats!$E$5,Stats!$E$11,"") | D9: 45712 | E9: =IFERROR(TODAY()-DATE(2000+MID(F9,SEARCH("-",F9,SEARCH("-",F9)+1)+1,2),MID(F9,SEARCH("-",F9,SEARCH("-",F9)+1)+3,2),MID(F9,SEARCH("-",F9,SEARCH("-",F9)+1)+5,2)),"") -> 463 | F9: 999-01-241106-11-091 | G9: o01/111 | H9: C57Bl/6J | I9: Male ♂ | J9: PE/EA/54-02/2019 | L9: Freely moving | M9: =COUNTA(D9)*COUNTA(F9)*COUNTA(J9)*COUNTA(L9) -> 1 | N9: 45688 | O9: S. Eszter | P9: AAV157 | Q9: AAV381 | S9: 1x, 1000 | T9: V1 | U9: -400 | V9: 400 | W9: left+righ | X9: 45698 | Y9: PL - Popara Lídia | AA9: 45863 | AB9: humane endpoint | AC9: szép gCampes állat, vis jelek, minden rétegben szép sejtek; allstaff\DATA\jasz.anna\VIP_dendrit\Measurements\VoltageSensors\FORCE\FORCE_checkup_202503212_2.mesc | AD9: 2025.02.28. fragments, N:\DATA\juhasz.gabor\Liliom\GCaMP6fCheckUpcage111all.mes | AE9: 2023-03-05 fragmented cells (n:\DATA\szalay.gergely\mes2025\check-up\2025-03-05_mous6_check-up.mes) | AF9: -
A10: Mouse_7 | B10: =IF((COUNTBLANK(AA10)=0),Stats!$E$7,IF((COUNTBLANK(N10)=0),IF((COUNTBLANK(X10)=0),IF((COUNTBLANK(AD10)=0),Stats!$E$6,Stats!$E$5),Stats!$E$4),"")) -> Death | C10: =IF(B10=Stats!$E$5,Stats!$E$11,"") | D10: 45712 | E10: =IFERROR(TODAY()-DATE(2000+MID(F10,SEARCH("-",F10,SEARCH("-",F10)+1)+1,2),MID(F10,SEARCH("-",F10,SEARCH("-",F10)+1)+3,2),MID(F10,SEARCH("-",F10,SEARCH("-",F10)+1)+5,2)),"") -> 463 | F10: 999-01-241106-11-092 | G10: o01/111 | H10: C57Bl/6J | I10: Male ♂ | J10: PE/EA/54-02/2019 | L10: Freely moving | M10: =COUNTA(D10)*COUNTA(F10)*COUNTA(J10)*COUNTA(L10) -> 1 | N10: 45688 | O10: S. Eszter | P10: AAV157 | Q10: AAV381 | S10: 1x, 1000 | T10: V1 | U10: -400 | V10: 400 | W10: double left | X10: 45698 | Y10: PL - Popara Lídia | AA10: 45863 | AB10: humane endpoint | AC10: szép gCamp jel visstimre is, szómák mélyen 500körül, iráényszelektív; allstaff\DATA\jasz.anna\VIP_dendrit\Measurements\VoltageSensors\FORCE\FORCE_checkup_202503212_2.mesc | AD10: 2025.02.28. fragments, N:\DATA\juhasz.gabor\Liliom\GCaMP6fCheckUpcage111all.mes | AE10: 2023-03-05 fragmented cells (n:\DATA\szalay.gergely\mes2025\check-up\2025-03-05_mous7_check-up.mes) | AF10: -
A11: Mouse_8 | B11: =IF((COUNTBLANK(AA11)=0),Stats!$E$7,IF((COUNTBLANK(N11)=0),IF((COUNTBLANK(X11)=0),IF((COUNTBLANK(AD11)=0),Stats!$E$6,Stats!$E$5),Stats!$E$4),"")) -> Death | C11: =IF(B11=Stats!$E$5,Stats!$E$11,"") | D11: 45712 | E11: =IFERROR(TODAY()-DATE(2000+MID(F11,SEARCH("-",F11,SEARCH("-",F11)+1)+1,2),MID(F11,SEARCH("-",F11,SEARCH("-",F11)+1)+3,2),MID(F11,SEARCH("-",F11,SEARCH("-",F11)+1)+5,2)),"") -> 458 | F11: 999-01-241111-11-032 | G11: o01/112 | H11: C57Bl/6J | I11: Male ♂ | J11: PE/EA/54-02/2019 | L11: Freely moving | M11: =COUNTA(D11)*COUNTA(F11)*COUNTA(J11)*COUNTA(L11) -> 1 | N11: 45688 | O11: S. Eszter | P11: AG54 | S11: 1x | T11: V1 | U11: -400 | V11: 400 | W11: left | X11: 45698 | Y11: WK - Wéber Katalin | AA11: 45721 | AB11: anatomical test | AD11: - | AE11: 2023-03-05 weak labeling, no signal (n:\DATA\szalay.gergely\mes2025\check-up\2025-03-05_mouse8_check-up.mes) | AF11: -
A12: Mouse_9 | B12: =IF((COUNTBLANK(AA12)=0),Stats!$E$7,IF((COUNTBLANK(N12)=0),IF((COUNTBLANK(X12)=0),IF((COUNTBLANK(AD12)=0),Stats!$E$6,Stats!$E$5),Stats!$E$4),"")) -> Death | C12: =IF(B12=Stats!$E$5,Stats!$E$11,"") | D12: 45712 | E12: =IFERROR(TODAY()-DATE(2000+MID(F12,SEARCH("-",F12,SEARCH("-",F12)+1)+1,2),MID(F12,SEARCH("-",F12,SEARCH("-",F12)+1)+3,2),MID(F12,SEARCH("-",F12,SEARCH("-",F12)+1)+5,2)),"") -> 458 | F12: 999-01-241111-11-033 | G12: o01/112 | H12: C57Bl/6J | I12: Male ♂ | J12: PE/EA/54-02/2019 | L12: Freely moving | M12: =COUNTA(D12)*COUNTA(F12)*COUNTA(J12)*COUNTA(L12) -> 1 | N12: 45688 | O12: S. Eszter | P12: AG54 | S12: 1x | T12: V1 | U12: -400 | V12: 400 | W12: right | X12: 45698 | Y12: WK - Wéber Katalin | AA12: 45863 | AB12: humane endpoint | AC12: szép exp., jelek vannak, van köztük szép is, sejtek mindenhol; allstaff\DATA\jasz.anna\VIP_dendrit\Measurements\VoltageSensors\FORCE\FORCE_checkup_202503211.mesc | AD12: -
A13: Mouse_10 | B13: =IF((COUNTBLANK(AA13)=0),Stats!$E$7,IF((COUNTBLANK(N13)=0),IF((COUNTBLANK(X13)=0),IF((COUNTBLANK(AD13)=0),Stats!$E$6,Stats!$E$5),Stats!$E$4),"")) -> Death | C13: =IF(B13=Stats!$E$5,Stats!$E$11,"") | D13: 45712 | E13: =IFERROR(TODAY()-DATE(2000+MID(F13,SEARCH("-",F13,SEARCH("-",F13)+1)+1,2),MID(F13,SEARCH("-",F13,SEARCH("-",F13)+1)+3,2),MID(F13,SEARCH("-",F13,SEARCH("-",F13)+1)+5,2)),"") -> 458 | F13: 999-01-241111-11-034 | G13: o01/112 | H13: C57Bl/6J | I13: Male ♂ | J13: PE/EA/54-02/2019 | L13: Freely moving | M13: =COUNTA(D13)*COUNTA(F13)*COUNTA(J13)*COUNTA(L13) -> 1 | N13: 45688 | O13: S. Eszter | P13: AG54 | S13: 10x | T13: V1 | U13: -400 | V13: 400 | W13: left+righ | X13: 45698 | Y13: WK - Wéber Katalin | AA13: 45863 | AB13: humane endpoint | AC13: van szép expr., de kevés sejten, mélyen 400-500 között azokon van jel is Measurements\VoltageSensors\FORCE\FORCE_checkup_202503212_2.mesc | AD13: - | AE13: 2025-03-05 endothel labeling (n:\DATA\szalay.gergely\mes2025\check-up\2025-03-05_mouse10_check-up.mes) | AF13: !!!
A14: Mouse_11 | B14: =IF((COUNTBLANK(AA14)=0),Stats!$E$7,IF((COUNTBLANK(N14)=0),IF((COUNTBLANK(X14)=0),IF((COUNTBLANK(AD14)=0),Stats!$E$6,Stats!$E$5),Stats!$E$4),"")) -> Death | C14: =IF(B14=Stats!$E$5,Stats!$E$11,"") | D14: 45712 | E14: =IFERROR(TODAY()-DATE(2000+MID(F14,SEARCH("-",F14,SEARCH("-",F14)+1)+1,2),MID(F14,SEARCH("-",F14,SEARCH("-",F14)+1)+3,2),MID(F14,SEARCH("-",F14,SEARCH("-",F14)+1)+5,2)),"") -> 458 | F14: 999-01-241111-11-035 | G14: o01/112 | H14: C57Bl/6J | I14: Male ♂ | J14: PE/EA/54-02/2019 | L14: Freely moving | M14: =COUNTA(D14)*COUNTA(F14)*COUNTA(J14)*COUNTA(L14) -> 1 | N14: 45688 | O14: S. Eszter | P14: AG54 | S14: 10x | T14: V1 | U14: -400 | V14: 400 | W14: no sign | X14: 45698 | Y14: WK - Wéber Katalin | AA14: 45721 | AB14: anatomical test | AD14: - | AE14: 2023-03-05 weak labeling, no signal (n:\DATA\szalay.gergely\mes2025\check-up\2025-03-05_mouse14_check-up.mes) | AF14: -
A15: Mouse_12 | B15: =IF((COUNTBLANK(AA15)=0),Stats!$E$7,IF((COUNTBLANK(N15)=0),IF((COUNTBLANK(X15)=0),IF((COUNTBLANK(AD15)=0),Stats!$E$6,Stats!$E$5),Stats!$E$4),"")) -> Death | C15: =IF(B15=Stats!$E$5,Stats!$E$11,"") | D15: 45712 | E15: =IFERROR(TODAY()-DATE(2000+MID(F15,SEARCH("-",F15,SEARCH("-",F15)+1)+1,2),MID(F15,SEARCH("-",F15,SEARCH("-",F15)+1)+3,2),MID(F15,SEARCH("-",F15,SEARCH("-",F15)+1)+5,2)),"") -> 499 | F15: 999-01-241001-21-051 | G15: o01/114 | H15: C57Bl/6J | I15: Female ♀ | J15: PE/EA/54-02/2019 | L15: Freely moving | M15: =COUNTA(D15)*COUNTA(F15)*COUNTA(J15)*COUNTA(L15) -> 1 | N15: 45688 | O15: S. Eszter | P15: AG54 | S15: 1x | T15: V1 | U15: -400 | V15: 400 | W15: no sign | X15: 45705 | Y15: WK - Wéber Katalin | AA15: 45863 | AB15: humane endpoint | AD15: - | AE15: 2023-03-05 weak labeling, no signal (n:\DATA\szalay.gergely\mes2025\check-up\2025-03-05_mouse12_check-up.mes) | AF15: atlas checkup: ‪\\192.168.42.3\allstaff\DATA\kertesz.borbala\2025.03.13.m12_m13_m15_checkup.mesc
A16: Mouse_13 | B16: =IF((COUNTBLANK(AA16)=0),Stats!$E$7,IF((COUNTBLANK(N16)=0),IF((COUNTBLANK(X16)=0),IF((COUNTBLANK(AD16)=0),Stats!$E$6,Stats!$E$5),Stats!$E$4),"")) -> Death | C16: =IF(B16=Stats!$E$5,Stats!$E$11,"") | D16: 45712 | E16: =IFERROR(TODAY()-DATE(2000+MID(F16,SEARCH("-",F16,SEARCH("-",F16)+1)+1,2),MID(F16,SEARCH("-",F16,SEARCH("-",F16)+1)+3,2),MID(F16,SEARCH("-",F16,SEARCH("-",F16)+1)+5,2)),"") -> 499 | F16: 999-01-241001-21-052 | G16: o01/114 | H16: C57Bl/6J | I16: Female ♀ | J16: PE/EA/54-02/2019 | L16: Freely moving | M16: =COUNTA(D16)*COUNTA(F16)*COUNTA(J16)*COUNTA(L16) -> 1 | N16: 45688 | O16: S. Eszter | P16: AG54 | S16: 10x | T16: V1 | U16: -400 | V16: 400 | W16: left | X16: 45705 | Y16: WK - Wéber Katalin | AA16: 45863 | AB16: humane endpoint | AD16: - | AE16: 2023-03-05 bown regrown | AF16: atlas checkup: ‪\\192.168.42.3\allstaff\DATA\kertesz.borbala\2025.03.13.m12_m13_m15_checkup.mesc
A17: Mouse_14 | B17: =IF((COUNTBLANK(AA17)=0),Stats!$E$7,IF((COUNTBLANK(N17)=0),IF((COUNTBLANK(X17)=0),IF((COUNTBLANK(AD17)=0),Stats!$E$6,Stats!$E$5),Stats!$E$4),"")) -> Death | C17: =IF(B17=Stats!$E$5,Stats!$E$11,"") | D17: 45712 | E17: =IFERROR(TODAY()-DATE(2000+MID(F17,SEARCH("-",F17,SEARCH("-",F17)+1)+1,2),MID(F17,SEARCH("-",F17,SEARCH("-",F17)+1)+3,2),MID(F17,SEARCH("-",F17,SEARCH("-",F17)+1)+5,2)),"") -> 499 | F17: 999-01-241001-21-053 | G17: o01/114 | H17: C57Bl/6J | I17: Female ♀ | J17: PE/EA/54-02/2019 | L17: Freely moving | M17: =COUNTA(D17)*COUNTA(F17)*COUNTA(J17)*COUNTA(L17) -> 1 | N17: 45688 | O17: S. Eszter | P17: AG54 | S17: 10x | T17: V1 | U17: -400 | V17: 400 | W17: right | X17: 45705 | Y17: WK - Wéber Katalin | AA17: 45863 | AB17: humane endpoint | AC17: szép expresszió, minden rétegben, szép jel, kicsit már öregszik; allstaff\DATA\jasz.anna\VIP_dendrit\Measurements\VoltageSensors\FORCE\FORCE_checkup_202503210.mesc | AD17: 2025.02.27. no expression N:\DATA\soos.andras.aron\FORCE_checkup.mes | AE17: 2023-03-05 weak labeling, no signal (n:\DATA\szalay.gergely\mes2025\check-up\2025-03-05_mouse14_check-up.mes) | AF17: N:\DATA\soos.andras.aron\m14_250307_force_vsstim.mesc
A18: Mouse_15 | B18: =IF((COUNTBLANK(AA18)=0),Stats!$E$7,IF((COUNTBLANK(N18)=0),IF((COUNTBLANK(X18)=0),IF((COUNTBLANK(AD18)=0),Stats!$E$6,Stats!$E$5),Stats!$E$4),"")) -> Death | C18: =IF(B18=Stats!$E$5,Stats!$E$11,"") | D18: 45712 | E18: =IFERROR(TODAY()-DATE(2000+MID(F18,SEARCH("-",F18,SEARCH("-",F18)+1)+1,2),MID(F18,SEARCH("-",F18,SEARCH("-",F18)+1)+3,2),MID(F18,SEARCH("-",F18,SEARCH("-",F18)+1)+5,2)),"") -> 499 | F18: 999-01-241001-21-054 | G18: o01/114 | H18: C57Bl/6J | I18: Female ♀ | J18: PE/EA/54-02/2019 | L18: Freely moving | M18: =COUNTA(D18)*COUNTA(F18)*COUNTA(J18)*COUNTA(L18) -> 1 | N18: 45688 | O18: S. Eszter | P18: AG54 | S18: 10x | T18: V1 | U18: -400 | V18: 400 | W18: left+righ | X18: 45705 | Y18: WK - Wéber Katalin | AA18: 45863 | AB18: humane endpoint | AD18: 2025.02.27. no expression N:\DATA\soos.andras.aron\FORCE_checkup.mes | AE18: 2023-03-05 weak labeling, no signal (n:\DATA\szalay.gergely\mes2025\check-up\2025-03-05_mouse15_check-up.mes) | AF18: atlas checkup: ‪\\192.168.42.3\allstaff\DATA\kertesz.borbala\2025.03.13.m12_m13_m15_checkup.mesc
A19: Mouse_16 | B19: =IF((COUNTBLANK(AA19)=0),Stats!$E$7,IF((COUNTBLANK(N19)=0),IF((COUNTBLANK(X19)=0),IF((COUNTBLANK(AD19)=0),Stats!$E$6,Stats!$E$5),Stats!$E$4),"")) -> Death | C19: Behavior | D19: 45712 | E19: =IFERROR(TODAY()-DATE(2000+MID(F19,SEARCH("-",F19,SEARCH("-",F19)+1)+1,2),MID(F19,SEARCH("-",F19,SEARCH("-",F19)+1)+3,2),MID(F19,SEARCH("-",F19,SEARCH("-",F19)+1)+5,2)),"") -> 461 | F19: A9F-01-24110821-111/356025 | G19: o01/116 | H19: TG_GCaMP6s_DA | I19: Female ♀ | J19: PE/EA/54-02/2019 | K19: Tarján Balázs | L19: Freely moving | M19: =COUNTA(D19)*COUNTA(F19)*COUNTA(J19)*COUNTA(L19) -> 1 | N19: - | O19: - | X19: 45706 | Y19: WK - Wéber Katalin | AA19: 45931 | AB19: death (lost headplate) | AD19: 2025.02.27. nice expression N:\DATA\soos.andras.aron\Gcamp6s_Force_checkup_116_111_113_114.mes | AE19: 2025.07.10. nice, N:\DATA\tarjan.balazs\2025.07.10.checkup-cage116-m32\2025-07-10-cage116null-cage116left1-m32_checkup.mesc | AF19: -
A20: Mouse_17 | B20: =IF((COUNTBLANK(AA20)=0),Stats!$E$7,IF((COUNTBLANK(N20)=0),IF((COUNTBLANK(X20)=0),IF((COUNTBLANK(AD20)=0),Stats!$E$6,Stats!$E$5),Stats!$E$4),"")) -> Death | C20: Behavior | D20: 45712 | E20: =IFERROR(TODAY()-DATE(2000+MID(F20,SEARCH("-",F20,SEARCH("-",F20)+1)+1,2),MID(F20,SEARCH("-",F20,SEARCH("-",F20)+1)+3,2),MID(F20,SEARCH("-",F20,SEARCH("-",F20)+1)+5,2)),"") -> 461 | F20: A9F-01-24110821-111/356026 | G20: o01/116 | H20: TG_GCaMP6s_DA | I20: Female ♀ | J20: PE/EA/54-02/2019 | K20: Tarján Balázs | L20: Freely moving | M20: =COUNTA(D20)*COUNTA(F20)*COUNTA(J20)*COUNTA(L20) -> 1 | N20: - | O20: - | X20: 45706 | Y20: WK - Wéber Katalin | AA20: 45931 | AB20: death (lost headplate) | AD20: 2025.02.27. nice expression N:\DATA\soos.andras.aron\Gcamp6s_Force_checkup_116_111_113_114.mes | AE20: 2025.07.10. nice, N:\DATA\tarjan.balazs\2025.07.10.checkup-cage116-m32\2025-07-10-cage116null-cage116left1-m32_checkup.mesc | AF20: -
A21: Mouse_18 | B21: =IF((COUNTBLANK(AA21)=0),Stats!$E$7,IF((COUNTBLANK(N21)=0),IF((COUNTBLANK(X21)=0),IF((COUNTBLANK(AD21)=0),Stats!$E$6,Stats!$E$5),Stats!$E$4),"")) -> Experiment | C21: Behavior | D21: 45712 | E21: =IFERROR(TODAY()-DATE(2000+MID(F21,SEARCH("-",F21,SEARCH("-",F21)+1)+1,2),MID(F21,SEARCH("-",F21,SEARCH("-",F21)+1)+3,2),MID(F21,SEARCH("-",F21,SEARCH("-",F21)+1)+5,2)),"") -> 433 | F21: A9F-01-241206-11-049 | G21: o01/115 | H21: TG_GCaMP6s_DA | I21: Male ♂ | J21: PE/EA/54-02/2019 | K21: Tarján Balázs | L21: Freely moving | M21: =COUNTA(D21)*COUNTA(F21)*COUNTA(J21)*COUNTA(L21) -> 1 | N21: - | O21: - | W21: no | X21: 45706 | Y21: WK - Wéber Katalin | AD21: 2025.02.28. nice, N:\DATA\juhasz.gabor\Liliom\transgeneGCaMP6sCheckUp.mes | AE21: 2025.07.09. nice, N:\DATA\tarjan.balazs\2025.07.09.checkup-cage152-cage115\2025-07-09-cage152-cage115_checkup.mesc | AF21: -
A22: Mouse_19 | B22: =IF((COUNTBLANK(AA22)=0),Stats!$E$7,IF((COUNTBLANK(N22)=0),IF((COUNTBLANK(X22)=0),IF((COUNTBLANK(AD22)=0),Stats!$E$6,Stats!$E$5),Stats!$E$4),"")) -> Death | C22: =IF(B22=Stats!$E$5,Stats!$E$11,"") | D22: 45712 | E22: =IFERROR(TODAY()-DATE(2000+MID(F22,SEARCH("-",F22,SEARCH("-",F22)+1)+1,2),MID(F22,SEARCH("-",F22,SEARCH("-",F22)+1)+3,2),MID(F22,SEARCH("-",F22,SEARCH("-",F22)+1)+5,2)),"") -> 433 | F22: A9F-01-241206-11-052 | G22: o01/115 | H22: TG_GCaMP6s_DA | I22: Male ♂ | J22: PE/EA/54-02/2019 | L22: Freely moving | M22: =COUNTA(D22)*COUNTA(F22)*COUNTA(J22)*COUNTA(L22) -> 1 | N22: - | O22: - | W22: right | X22: 45706 | Y22: WK - Wéber Katalin | AA22: 45740 | AB22: death (lost headplate) | AD22: 2025.02.28. growth, N:\DATA\juhasz.gabor\Liliom\transgeneGCaMP6sCheckUp.mes | AF22: -
A23: Mouse_20 | B23: =IF((COUNTBLANK(AA23)=0),Stats!$E$7,IF((COUNTBLANK(N23)=0),IF((COUNTBLANK(X23)=0),IF((COUNTBLANK(AD23)=0),Stats!$E$6,Stats!$E$5),Stats!$E$4),"")) -> Experiment | C23: Behavior | D23: 45712 | E23: =IFERROR(TODAY()-DATE(2000+MID(F23,SEARCH("-",F23,SEARCH("-",F23)+1)+1,2),MID(F23,SEARCH("-",F23,SEARCH("-",F23)+1)+3,2),MID(F23,SEARCH("-",F23,SEARCH("-",F23)+1)+5,2)),"") -> 433 | F23: A9F-01-241206-11-049 | G23: o01/152 | H23: TG_GCaMP6s_DA | I23: Male ♂ | J23: PE/EA/54-02/2019 | K23: Tarján Balázs | L23: Freely moving | M23: =COUNTA(D23)*COUNTA(F23)*COUNTA(J23)*COUNTA(L23) -> 1 | N23: - | O23: - | W23: no | X23: 45706 | Y23: WK - Wéber Katalin | AD23: 2025.02.28. nice, N:\DATA\juhasz.gabor\Liliom\transgeneGCaMP6sCheckUp.mes | AE23: 2025.07.09. nice, N:\DATA\tarjan.balazs\2025.07.09.checkup-cage152-cage115\2025-07-09-cage152-cage115_checkup.mesc | AF23: -
A24: Mouse_21 | B24: =IF((COUNTBLANK(AA24)=0),Stats!$E$7,IF((COUNTBLANK(N24)=0),IF((COUNTBLANK(X24)=0),IF((COUNTBLANK(AD24)=0),Stats!$E$6,Stats!$E$5),Stats!$E$4),"")) -> Death | C24: =IF(B24=Stats!$E$5,Stats!$E$11,"") | D24: 45726 | E24: =IFERROR(TODAY()-DATE(2000+MID(F24,SEARCH("-",F24,SEARCH("-",F24)+1)+1,2),MID(F24,SEARCH("-",F24,SEARCH("-",F24)+1)+3,2),MID(F24,SEARCH("-",F24,SEARCH("-",F24)+1)+5,2)),"") -> 423 | F24: 628-49-241216-21-006 | G24: o01/112 | H24: Thy1-Cre | I24: Female ♀ | J24: PE/EA/54-02/2019 | L24: Freely moving | M24: =COUNTA(D24)*COUNTA(F24)*COUNTA(J24)*COUNTA(L24) -> 1 | N24: 45721 | O24: KB - Kocsis Bálint | P24: AG53 | Q24: AAV428 | S24: 1x,10x | T24: V1 | U24: -400 | V24: 400 | W24: left | X24: 45791 | AA24: 45835 | AB24: death (lost headplate) | AC24: PPKE in vitro-ra ; él, check up 2025/04/29
A25: Mouse_22 | B25: =IF((COUNTBLANK(AA25)=0),Stats!$E$7,IF((COUNTBLANK(N25)=0),IF((COUNTBLANK(X25)=0),IF((COUNTBLANK(AD25)=0),Stats!$E$6,Stats!$E$5),Stats!$E$4),"")) -> Death | C25: =IF(B25=Stats!$E$5,Stats!$E$11,"") | D25: 45726 | E25: =IFERROR(TODAY()-DATE(2000+MID(F25,SEARCH("-",F25,SEARCH("-",F25)+1)+1,2),MID(F25,SEARCH("-",F25,SEARCH("-",F25)+1)+3,2),MID(F25,SEARCH("-",F25,SEARCH("-",F25)+1)+5,2)),"") -> 423 | F25: 628-49-241216-21-007 | G25: o01/112 | H25: Thy1-Cre | I25: Female ♀ | J25: PE/EA/54-02/2019 | L25: Freely moving | M25: =COUNTA(D25)*COUNTA(F25)*COUNTA(J25)*COUNTA(L25) -> 1 | N25: 45721 | O25: KB - Kocsis Bálint | P25: AG53 | Q25: AAV428 | S25: 1x,10x | T25: V1 | U25: -400 | V25: 400 | W25: right | X25: 45791 | AA25: 45809 | AB25: death (other) | AC25: PPKE in vitro-ra
A26: Mouse_23 | B26: =IF((COUNTBLANK(AA26)=0),Stats!$E$7,IF((COUNTBLANK(N26)=0),IF((COUNTBLANK(X26)=0),IF((COUNTBLANK(AD26)=0),Stats!$E$6,Stats!$E$5),Stats!$E$4),"")) -> Death | C26: =IF(B26=Stats!$E$5,Stats!$E$11,"") | D26: 45726 | E26: =IFERROR(TODAY()-DATE(2000+MID(F26,SEARCH("-",F26,SEARCH("-",F26)+1)+1,2),MID(F26,SEARCH("-",F26,SEARCH("-",F26)+1)+3,2),MID(F26,SEARCH("-",F26,SEARCH("-",F26)+1)+5,2)),"") -> 423 | F26: 628-49-241216-21-008 | G26: o01/112 | H26: Thy1-Cre | I26: Female ♀ | J26: PE/EA/54-02/2019 | L26: Freely moving | M26: =COUNTA(D26)*COUNTA(F26)*COUNTA(J26)*COUNTA(L26) -> 1 | N26: 45721 | O26: KB - Kocsis Bálint | P26: AG53 | Q26: AAV428 | S26: 10x,10x | T26: V1 | U26: -400 | V26: 400 | W26: left+righ | X26: 45791 | AA26: 45809 | AB26: death (other) | AC26: PPKE in vitro-ra
A27: Mouse_24 | B27: =IF((COUNTBLANK(AA27)=0),Stats!$E$7,IF((COUNTBLANK(N27)=0),IF((COUNTBLANK(X27)=0),IF((COUNTBLANK(AD27)=0),Stats!$E$6,Stats!$E$5),Stats!$E$4),"")) -> Death | C27: Behavior | D27: 45726 | E27: =IFERROR(TODAY()-DATE(2000+MID(F27,SEARCH("-",F27,SEARCH("-",F27)+1)+1,2),MID(F27,SEARCH("-",F27,SEARCH("-",F27)+1)+3,2),MID(F27,SEARCH("-",F27,SEARCH("-",F27)+1)+5,2)),"") -> 423 | F27: 628-49-241216-21-009 | G27: o01/112 | H27: Thy1-Cre | I27: Female ♀ | J27: PE/EA/54-02/2019 | K27: Tarján Balázs | L27: Freely moving | M27: =COUNTA(D27)*COUNTA(F27)*COUNTA(J27)*COUNTA(L27) -> 1 | N27: 45721 | O27: KB - Kocsis Bálint | P27: AG53 | Q27: AAV428 | S27: 10x,10x | T27: V1 | U27: -400 | V27: 400 | W27: none | AA27: 45946 | AB27: death (lost headplate) | AC27: PPKE in vitro-ra , él, check up 2025/04/29 jó juelölés nincs, de valami van, nucleus festés ok
A28: Mouse_25 | B28: =IF((COUNTBLANK(AA28)=0),Stats!$E$7,IF((COUNTBLANK(N28)=0),IF((COUNTBLANK(X28)=0),IF((COUNTBLANK(AD28)=0),Stats!$E$6,Stats!$E$5),Stats!$E$4),"")) -> Death | C28: =IF(B28=Stats!$E$5,Stats!$E$11,"") | D28: 45726 | E28: =IFERROR(TODAY()-DATE(2000+MID(F28,SEARCH("-",F28,SEARCH("-",F28)+1)+1,2),MID(F28,SEARCH("-",F28,SEARCH("-",F28)+1)+3,2),MID(F28,SEARCH("-",F28,SEARCH("-",F28)+1)+5,2)),"") -> 419 | F28: 999-01-241220-11-048 | G28: o01/113 | H28: C57Bl/6J | I28: Male ♂ | J28: PE/EA/54-02/2019 | L28: Freely moving | M28: =COUNTA(D28)*COUNTA(F28)*COUNTA(J28)*COUNTA(L28) -> 1 | N28: 45720 | O28: PL - Popara Lídia | P28: AG55 | Q28: AAV428 | S28: 1x,10x | T28: V1 | U28: -300 | V28: 400 | W28: right | X28: 45720 | Y28: PL - Popara Lídia | AA28: 45958 | AB28: humane endpoint | AC28: J1 jelölésű egérben szép FORCE jel, DE 113 számú ketrec \\192.168.42.3\allstaff\DATA\soos.andras.aron\20250314_FORCE_checkup.mesc (beadási helyről fotó az Atlasz számítógépén desktopon: 2025-03-14_FORCEcheckup_m25_j1_113ketrec.ppt), befogható (!!!)
A29: Mouse_26 | B29: =IF((COUNTBLANK(AA29)=0),Stats!$E$7,IF((COUNTBLANK(N29)=0),IF((COUNTBLANK(X29)=0),IF((COUNTBLANK(AD29)=0),Stats!$E$6,Stats!$E$5),Stats!$E$4),"")) -> Death | C29: =IF(B29=Stats!$E$5,Stats!$E$11,"") | D29: 45726 | E29: =IFERROR(TODAY()-DATE(2000+MID(F29,SEARCH("-",F29,SEARCH("-",F29)+1)+1,2),MID(F29,SEARCH("-",F29,SEARCH("-",F29)+1)+3,2),MID(F29,SEARCH("-",F29,SEARCH("-",F29)+1)+5,2)),"") -> 419 | F29: 999-01-241220-11-049 | G29: o01/113 | H29: C57Bl/6J | I29: Male ♂ | J29: PE/EA/54-02/2019 | L29: Freely moving | M29: =COUNTA(D29)*COUNTA(F29)*COUNTA(J29)*COUNTA(L29) -> 1 | N29: 45720 | O29: PL - Popara Lídia | P29: AG55 | Q29: AAV428 | S29: 1x,10x | T29: V1 | U29: -300 | V29: 400 | W29: left | X29: 45720 | Y29: PL - Popara Lídia | AA29: 45958 | AB29: humane endpoint | AC29: szép jelölés, FORCE, jel is van, befogható(!!!)
A30: Mouse_27 | B30: =IF((COUNTBLANK(AA30)=0),Stats!$E$7,IF((COUNTBLANK(N30)=0),IF((COUNTBLANK(X30)=0),IF((COUNTBLANK(AD30)=0),Stats!$E$6,Stats!$E$5),Stats!$E$4),"")) -> Death | C30: =IF(B30=Stats!$E$5,Stats!$E$11,"") | D30: 45726 | E30: =IFERROR(TODAY()-DATE(2000+MID(F30,SEARCH("-",F30,SEARCH("-",F30)+1)+1,2),MID(F30,SEARCH("-",F30,SEARCH("-",F30)+1)+3,2),MID(F30,SEARCH("-",F30,SEARCH("-",F30)+1)+5,2)),"") -> 419 | F30: 999-01-241220-11-050 | G30: o01/113 | H30: C57Bl/6J | I30: Male ♂ | J30: PE/EA/54-02/2019 | L30: Freely moving | M30: =COUNTA(D30)*COUNTA(F30)*COUNTA(J30)*COUNTA(L30) -> 1 | N30: 45720 | O30: PL - Popara Lídia | P30: AG55 | Q30: AAV428 | S30: 10x,10x | T30: V1 | U30: -300 | V30: 400 | W30: none | X30: 45720 | Y30: PL - Popara Lídia | AA30: 45958 | AB30: humane endpoint | AC30: nagyon szép jel, FORCE, befogható(!!!)
A31: Mouse_28 | B31: =IF((COUNTBLANK(AA31)=0),Stats!$E$7,IF((COUNTBLANK(N31)=0),IF((COUNTBLANK(X31)=0),IF((COUNTBLANK(AD31)=0),Stats!$E$6,Stats!$E$5),Stats!$E$4),"")) -> Check-up | C31: Behavior | D31: 45726 | E31: =IFERROR(TODAY()-DATE(2000+MID(F31,SEARCH("-",F31,SEARCH("-",F31)+1)+1,2),MID(F31,SEARCH("-",F31,SEARCH("-",F31)+1)+3,2),MID(F31,SEARCH("-",F31,SEARCH("-",F31)+1)+5,2)),"") -> 419 | F31: 999-01-241220-11-059 | G31: o01/114 | H31: C57Bl/6J | I31: Male ♂ | J31: PE/EA/54-02/2019 | K31: Tarján Balázs | L31: Freely moving | M31: =COUNTA(D31)*COUNTA(F31)*COUNTA(J31)*COUNTA(L31) -> 1 | N31: 45720 | O31: PL - Popara Lídia | P31: AAV197 | Q31: AAV262 | S31: 10x,10x | T31: V1 | U31: -300 | V31: 400 | W31: left | X31: 45720 | Y31: PL - Popara Lídia | AC31: nagyon szép gCamp jel; N:\DATA\jasz.anna\VIP_dendrit\Measurements\VoltageSensors\FORCE\FORCE_checkup_202503212.mesc /12_2
A32: Mouse_29 | B32: =IF((COUNTBLANK(AA32)=0),Stats!$E$7,IF((COUNTBLANK(N32)=0),IF((COUNTBLANK(X32)=0),IF((COUNTBLANK(AD32)=0),Stats!$E$6,Stats!$E$5),Stats!$E$4),"")) -> Death | C32: Behavior | D32: 45726 | E32: =IFERROR(TODAY()-DATE(2000+MID(F32,SEARCH("-",F32,SEARCH("-",F32)+1)+1,2),MID(F32,SEARCH("-",F32,SEARCH("-",F32)+1)+3,2),MID(F32,SEARCH("-",F32,SEARCH("-",F32)+1)+5,2)),"") -> 419 | F32: 999-01-241220-11-060 | G32: o01/114 | H32: C57Bl/6J | I32: Male ♂ | J32: PE/EA/54-02/2019 | K32: Tarján Balázs | L32: Freely moving | N32: 45720 | O32: PL - Popara Lídia | P32: AAV197 | Q32: AAV262 | S32: 10000x,2x | T32: V1 | U32: -300 | V32: 400 | W32: right | X32: 45720 | Y32: PL - Popara Lídia | AA32: 45946 | AB32: death (lost headplate) | AC32: nagyon szép gCamp jel; N:\DATA\jasz.anna\VIP_dendrit\Measurements\VoltageSensors\FORCE\FORCE_checkup_202503212.mesc /12_2
A33: Mouse_30 | B33: =IF((COUNTBLANK(AA33)=0),Stats!$E$7,IF((COUNTBLANK(N33)=0),IF((COUNTBLANK(X33)=0),IF((COUNTBLANK(AD33)=0),Stats!$E$6,Stats!$E$5),Stats!$E$4),"")) -> Death | C33: =IF(B33=Stats!$E$5,Stats!$E$11,"") | D33: 45726 | E33: =IFERROR(TODAY()-DATE(2000+MID(F33,SEARCH("-",F33,SEARCH("-",F33)+1)+1,2),MID(F33,SEARCH("-",F33,SEARCH("-",F33)+1)+3,2),MID(F33,SEARCH("-",F33,SEARCH("-",F33)+1)+5,2)),"") -> 419 | F33: 999-01-241220-11-061 | G33: o01/111 | H33: C57Bl/6J | I33: Male ♂ | J33: PE/EA/54-02/2019 | L33: Freely moving | N33: 45723 | O33: PL - Popara Lídia | P33: AG49 | S33: 1x | T33: V1 | U33: -300 | V33: 400 | W33: left | X33: 45723 | Y33: PL - Popara Lídia | AA33: 45884 | AC33: JEDI
A34: Mouse_31 | B34: =IF((COUNTBLANK(AA34)=0),Stats!$E$7,IF((COUNTBLANK(N34)=0),IF((COUNTBLANK(X34)=0),IF((COUNTBLANK(AD34)=0),Stats!$E$6,Stats!$E$5),Stats!$E$4),"")) -> Death | C34: Anatomy | D34: 45726 | E34: =IFERROR(TODAY()-DATE(2000+MID(F34,SEARCH("-",F34,SEARCH("-",F34)+1)+1,2),MID(F34,SEARCH("-",F34,SEARCH("-",F34)+1)+3,2),MID(F34,SEARCH("-",F34,SEARCH("-",F34)+1)+5,2)),"") -> 458 | F34: 999-01-241111-21-036 | G34: o01/111 | H34: C57Bl/6J | I34: Female ♀ | J34: PE/EA/54-02/2019 | L34: Freely moving | M34: =COUNTA(D34)*COUNTA(F34)*COUNTA(J34)*COUNTA(L34) -> 1 | N34: 45723 | O34: PL - Popara Lídia | P34: AG49 | S34: 1x | T34: V1 | U34: -300 | V34: 400 | W34: left | X34: 45723 | Y34: PL - Popara Lídia | AA34: 45884 | AC34: JEDI
A35: Mouse_32 | B35: =IF((COUNTBLANK(AA35)=0),Stats!$E$7,IF((COUNTBLANK(N35)=0),IF((COUNTBLANK(X35)=0),IF((COUNTBLANK(AD35)=0),Stats!$E$6,Stats!$E$5),Stats!$E$4),"")) -> Experiment | C35: Behavior | D35: 45726 | E35: =IFERROR(TODAY()-DATE(2000+MID(F35,SEARCH("-",F35,SEARCH("-",F35)+1)+1,2),MID(F35,SEARCH("-",F35,SEARCH("-",F35)+1)+3,2),MID(F35,SEARCH("-",F35,SEARCH("-",F35)+1)+5,2)),"") -> 458 | F35: 999-01-241111-21-037 | G35: o01/111 | H35: Thy1-Cre | I35: Female ♀ | J35: PE/EA/54-02/2019 | K35: Tarján Balázs | L35: Freely moving | M35: =COUNTA(D35)*COUNTA(F35)*COUNTA(J35)*COUNTA(L35) -> 1 | N35: 45723 | O35: PL - Popara Lídia | P35: AAV262 | S35: 5x | T35: V1 | U35: -300 | V35: 400 | W35: both | X35: 45723 | Y35: PL - Popara Lídia | AC35: injektálási területen benövés, szép jelölés postero laterális részen | AD35: 45742 | AE35: 2025.07.10. csontbenoves, N:\DATA\tarjan.balazs\2025.07.10.checkup-cage116-m32\2025-07-10-cage116null-cage116left1-m32_checkup.mesc
A36: Mouse_33 | B36: =IF((COUNTBLANK(AA36)=0),Stats!$E$7,IF((COUNTBLANK(N36)=0),IF((COUNTBLANK(X36)=0),IF((COUNTBLANK(AD36)=0),Stats!$E$6,Stats!$E$5),Stats!$E$4),"")) -> Experiment | C36: Behavior | D36: 45726 | E36: =IFERROR(TODAY()-DATE(2000+MID(F36,SEARCH("-",F36,SEARCH("-",F36)+1)+1,2),MID(F36,SEARCH("-",F36,SEARCH("-",F36)+1)+3,2),MID(F36,SEARCH("-",F36,SEARCH("-",F36)+1)+5,2)),"") -> 458 | F36: 999-01-241111-21-038 | G36: o01/111 | H36: Thy1-Cre | I36: Female ♀ | J36: PE/EA/54-02/2019 | K36: Tarján Balázs | L36: Freely moving | M36: =COUNTA(D36)*COUNTA(F36)*COUNTA(J36)*COUNTA(L36) -> 1 | N36: 45723 | O36: PL - Popara Lídia | P36: AAV262 | S36: 5x | T36: V1 | U36: -300 | V36: 400 | W36: none | X36: 45723 | Y36: PL - Popara Lídia | AC36: kis benövés, szép jelölés | AD36: 45742
A37: Mouse_34 | B37: =IF((COUNTBLANK(AA37)=0),Stats!$E$7,IF((COUNTBLANK(N37)=0),IF((COUNTBLANK(X37)=0),IF((COUNTBLANK(AD37)=0),Stats!$E$6,Stats!$E$5),Stats!$E$4),"")) -> Death | C37: To define | D37: 45726 | E37: =IFERROR(TODAY()-DATE(2000+MID(F37,SEARCH("-",F37,SEARCH("-",F37)+1)+1,2),MID(F37,SEARCH("-",F37,SEARCH("-",F37)+1)+3,2),MID(F37,SEARCH("-",F37,SEARCH("-",F37)+1)+5,2)),"") -> 423 | F37: 628-49-241216-21-010 | G37: o01/116 | H37: C57Bl/6J | I37: Male ♂ | J37: PE/EA/00329-6/2025 | L37: Other | N37: 45718 | O37: PL - Popara Lídia | P37: AAV500 | T37: V1 | U37: -300 | V37: 400 | W37: left | X37: 45718 | Y37: PL - Popara Lídia | AA37: 45922 | AB37: anatomical test | AC37: lila cetlis 113 ketrec, bal egér - pár sejtszerű cucc (10-15um) -50 környékén, aktivitást nem láttam de talán, lejjebb semmi. \\192.168.42.3\allstaff\DATA\kertesz.borbala\_2025\3lilacetlis_force_checkup_250315.mesc
A38: Mouse_35 | B38: =IF((COUNTBLANK(AA38)=0),Stats!$E$7,IF((COUNTBLANK(N38)=0),IF((COUNTBLANK(X38)=0),IF((COUNTBLANK(AD38)=0),Stats!$E$6,Stats!$E$5),Stats!$E$4),"")) -> Death | C38: To define | D38: 45726 | E38: =IFERROR(TODAY()-DATE(2000+MID(F38,SEARCH("-",F38,SEARCH("-",F38)+1)+1,2),MID(F38,SEARCH("-",F38,SEARCH("-",F38)+1)+3,2),MID(F38,SEARCH("-",F38,SEARCH("-",F38)+1)+5,2)),"") -> 423 | F38: 628-49-241216-21-011 | G38: o01/116 | H38: C57Bl/6J | I38: Male ♂ | J38: PE/EA/00329-6/2025 | L38: Other | N38: 45718 | O38: PL - Popara Lídia | P38: AAV500 | T38: V1 | U38: -300 | V38: 400 | W38: none | X38: 45718 | Y38: PL - Popara Lídia | AA38: 45922 | AB38: anatomical test | AC38: lila cetlis 113 ketrec, bal-jobb egér - -250 körül volt egy sejt, szerintem aktivitás is. \\192.168.42.3\allstaff\DATA\kertesz.borbala\_2025\3lilacetlis_force_checkup_250315.mesc
A39: Mouse_36 | B39: =IF((COUNTBLANK(AA39)=0),Stats!$E$7,IF((COUNTBLANK(N39)=0),IF((COUNTBLANK(X39)=0),IF((COUNTBLANK(AD39)=0),Stats!$E$6,Stats!$E$5),Stats!$E$4),"")) -> Death | C39: To define | D39: 45726 | E39: =IFERROR(TODAY()-DATE(2000+MID(F39,SEARCH("-",F39,SEARCH("-",F39)+1)+1,2),MID(F39,SEARCH("-",F39,SEARCH("-",F39)+1)+3,2),MID(F39,SEARCH("-",F39,SEARCH("-",F39)+1)+5,2)),"") -> 423 | F39: 628-49-241216-21-012 | G39: o01/116 | H39: C57Bl/6J | I39: Male ♂ | J39: PE/EA/00329-6/2025 | L39: Other | N39: 45718 | O39: PL - Popara Lídia | P39: AAV500 | T39: V1 | U39: -300 | V39: 400 | W39: both | X39: 45718 | Y39: PL - Popara Lídia | AA39: 45922 | AB39: anatomical test | AC39: lila cetlis 113 ketrec, bal-jobb egér - -100 körül vannak sejtek, aktivitásról nem vagyok meggyőzve. \\192.168.42.3\allstaff\DATA\kertesz.borbala\_2025\3lilacetlis_force_checkup_250315.mesc
A40: Mouse_37 | B40: =IF((COUNTBLANK(AA40)=0),Stats!$E$7,IF((COUNTBLANK(N40)=0),IF((COUNTBLANK(X40)=0),IF((COUNTBLANK(AD40)=0),Stats!$E$6,Stats!$E$5),Stats!$E$4),"")) -> Death | C40: To define | D40: 45726 | E40: =IFERROR(TODAY()-DATE(2000+MID(F40,SEARCH("-",F40,SEARCH("-",F40)+1)+1,2),MID(F40,SEARCH("-",F40,SEARCH("-",F40)+1)+3,2),MID(F40,SEARCH("-",F40,SEARCH("-",F40)+1)+5,2)),"") -> 423 | F40: 628-49-241216-21-013 | G40: o01/116 | H40: C57Bl/6J | I40: Male ♂ | J40: PE/EA/00329-6/2025 | N40: 45718 | O40: PL - Popara Lídia | P40: AG54 | T40: V1 | U40: -300 | V40: 400 | W40: double left | X40: 45718 | Y40: PL - Popara Lídia | AA40: 45918 | AB40: death (lost headplate) | AC40: van kifejeződés, FORCE, jel is, mouse 38, befogható(!!!)
...

Sheet Summary Liliom
A1: All animals stats | H1: Usage by line
A2: Project | B2: State | F2: Alive
B3: Death | C3: Injected | D3: Check-up | E3: Experiment | H3: Line | I3: Animals
B4: =COUNTIFS('old -- All injections Dobos'!$C$2:$C$3002,'Summary Liliom'!$A4,'old -- All injections Dobos'!$B$2:$B$3002,'Summary Liliom'!B$3) -> 0 | C4: =COUNTIFS('old -- All injections Dobos'!$C$2:$C$3002,'Summary Liliom'!$A4,'old -- All injections Dobos'!$B$2:$B$3002,'Summary Liliom'!C$3) -> 0 | D4: =COUNTIFS('old -- All injections Dobos'!$C$2:$C$3002,'Summary Liliom'!$A4,'old -- All injections Dobos'!$B$2:$B$3002,'Summary Liliom'!D$3) -> 0 | E4: =COUNTIFS('old -- All injections Dobos'!$C$2:$C$3002,'Summary Liliom'!$A4,'old -- All injections Dobos'!$B$2:$B$3002,'Summary Liliom'!E$3) -> 0 | F4: =SUM(C4:E4) -> 0 | H4: =IF(COUNTA(Stats!G4)=1,Stats!G4,"") -> BAC-pva/gfp | I4: =COUNTIFS('old -- All injections Dobos'!J$2:J$3002,'Summary Liliom'!$H4) -> 10
A5: =IF(COUNTA(Stats!E20)=1,Stats!E20,"") -> ASO | B5: =COUNTIFS('old -- All injections Dobos'!$C$2:$C$3002,'Summary Liliom'!$A5,'old -- All injections Dobos'!$B$2:$B$3002,'Summary Liliom'!B$3) -> 86 | C5: =COUNTIFS('old -- All injections Dobos'!$C$2:$C$3002,'Summary Liliom'!$A5,'old -- All injections Dobos'!$B$2:$B$3002,'Summary Liliom'!C$3) -> 0 | D5: =COUNTIFS('old -- All injections Dobos'!$C$2:$C$3002,'Summary Liliom'!$A5,'old -- All injections Dobos'!$B$2:$B$3002,'Summary Liliom'!D$3) -> 0 | E5: =COUNTIFS('old -- All injections Dobos'!$C$2:$C$3002,'Summary Liliom'!$A5,'old -- All injections Dobos'!$B$2:$B$3002,'Summary Liliom'!E$3) -> 0 | F5: =SUM(C5:E5) -> 0 | H5: =IF(COUNTA(Stats!G5)=1,Stats!G5,"") -> C57Bl/6J | I5: =COUNTIFS('old -- All injections Dobos'!J$2:J$3002,'Summary Liliom'!$H5) -> 0
A6: =IF(COUNTA(Stats!E21)=1,Stats!E21,"") -> Collaboration | B6: =COUNTIFS('old -- All injections Dobos'!$C$2:$C$3002,'Summary Liliom'!$A6,'old -- All injections Dobos'!$B$2:$B$3002,'Summary Liliom'!B$3) -> 39 | C6: =COUNTIFS('old -- All injections Dobos'!$C$2:$C$3002,'Summary Liliom'!$A6,'old -- All injections Dobos'!$B$2:$B$3002,'Summary Liliom'!C$3) -> 0 | D6: =COUNTIFS('old -- All injections Dobos'!$C$2:$C$3002,'Summary Liliom'!$A6,'old -- All injections Dobos'!$B$2:$B$3002,'Summary Liliom'!D$3) -> 0 | E6: =COUNTIFS('old -- All injections Dobos'!$C$2:$C$3002,'Summary Liliom'!$A6,'old -- All injections Dobos'!$B$2:$B$3002,'Summary Liliom'!E$3) -> 0 | F6: =SUM(C6:E6) -> 0 | H6: =IF(COUNTA(Stats!G6)=1,Stats!G6,"") -> C57Bl6/NTac | I6: =COUNTIFS('old -- All injections Dobos'!J$2:J$3002,'Summary Liliom'!$H6) -> 0
A7: =IF(COUNTA(Stats!E22)=1,Stats!E22,"") -> Columna | B7: =COUNTIFS('old -- All injections Dobos'!$C$2:$C$3002,'Summary Liliom'!$A7,'old -- All injections Dobos'!$B$2:$B$3002,'Summary Liliom'!B$3) -> 222 | C7: =COUNTIFS('old -- All injections Dobos'!$C$2:$C$3002,'Summary Liliom'!$A7,'old -- All injections Dobos'!$B$2:$B$3002,'Summary Liliom'!C$3) -> 0 | D7: =COUNTIFS('old -- All injections Dobos'!$C$2:$C$3002,'Summary Liliom'!$A7,'old -- All injections Dobos'!$B$2:$B$3002,'Summary Liliom'!D$3) -> 0 | E7: =COUNTIFS('old -- All injections Dobos'!$C$2:$C$3002,'Summary Liliom'!$A7,'old -- All injections Dobos'!$B$2:$B$3002,'Summary Liliom'!E$3) -> 0 | F7: =SUM(C7:E7) -> 0 | H7: =IF(COUNTA(Stats!G7)=1,Stats!G7,"") -> FVB/Ant | I7: =COUNTIFS('old -- All injections Dobos'!J$2:J$3002,'Summary Liliom'!$H7) -> 9
A8: =IF(COUNTA(Stats!E23)=1,Stats!E23,"") -> MS23 | B8: =COUNTIFS('old -- All injections Dobos'!$C$2:$C$3002,'Summary Liliom'!$A8,'old -- All injections Dobos'!$B$2:$B$3002,'Summary Liliom'!B$3) -> 80 | C8: =COUNTIFS('old -- All injections Dobos'!$C$2:$C$3002,'Summary Liliom'!$A8,'old -- All injections Dobos'!$B$2:$B$3002,'Summary Liliom'!C$3) -> 0 | D8: =COUNTIFS('old -- All injections Dobos'!$C$2:$C$3002,'Summary Liliom'!$A8,'old -- All injections Dobos'!$B$2:$B$3002,'Summary Liliom'!D$3) -> 0 | E8: =COUNTIFS('old -- All injections Dobos'!$C$2:$C$3002,'Summary Liliom'!$A8,'old -- All injections Dobos'!$B$2:$B$3002,'Summary Liliom'!E$3) -> 0 | F8: =SUM(C8:E8) -> 0 | H8: =IF(COUNTA(Stats!G8)=1,Stats!G8,"") -> PV-FLP | I8: =COUNTIFS('old -- All injections Dobos'!J$2:J$3002,'Summary Liliom'!$H8) -> 3
A9: =IF(COUNTA(Stats!E24)=1,Stats!E24,"") -> MS71 | B9: =COUNTIFS('old -- All injections Dobos'!$C$2:$C$3002,'Summary Liliom'!$A9,'old -- All injections Dobos'!$B$2:$B$3002,'Summary Liliom'!B$3) -> 5 | C9: =COUNTIFS('old -- All injections Dobos'!$C$2:$C$3002,'Summary Liliom'!$A9,'old -- All injections Dobos'!$B$2:$B$3002,'Summary Liliom'!C$3) -> 0 | D9: =COUNTIFS('old -- All injections Dobos'!$C$2:$C$3002,'Summary Liliom'!$A9,'old -- All injections Dobos'!$B$2:$B$3002,'Summary Liliom'!D$3) -> 0 | E9: =COUNTIFS('old -- All injections Dobos'!$C$2:$C$3002,'Summary Liliom'!$A9,'old -- All injections Dobos'!$B$2:$B$3002,'Summary Liliom'!E$3) -> 0 | F9: =SUM(C9:E9) -> 0 | H9: =IF(COUNTA(Stats!G9)=1,Stats!G9,"") -> TG_GCaMP6s_DA | I9: =COUNTIFS('old -- All injections Dobos'!J$2:J$3002,'Summary Liliom'!$H9) -> 0
A10: =IF(COUNTA(Stats!E25)=1,Stats!E25,"") -> Moculus | B10: =COUNTIFS('old -- All injections Dobos'!$C$2:$C$3002,'Summary Liliom'!$A10,'old -- All injections Dobos'!$B$2:$B$3002,'Summary Liliom'!B$3) -> 68 | C10: =COUNTIFS('old -- All injections Dobos'!$C$2:$C$3002,'Summary Liliom'!$A10,'old -- All injections Dobos'!$B$2:$B$3002,'Summary Liliom'!C$3) -> 0 | D10: =COUNTIFS('old -- All injections Dobos'!$C$2:$C$3002,'Summary Liliom'!$A10,'old -- All injections Dobos'!$B$2:$B$3002,'Summary Liliom'!D$3) -> 0 | E10: =COUNTIFS('old -- All injections Dobos'!$C$2:$C$3002,'Summary Liliom'!$A10,'old -- All injections Dobos'!$B$2:$B$3002,'Summary Liliom'!E$3) -> 0 | F10: =SUM(C10:E10) -> 0 | H10: =IF(COUNTA(Stats!G10)=1,Stats!G10,"") -> TG_GCaMP6F(82) | I10: =COUNTIFS('old -- All injections Dobos'!J$2:J$3002,'Summary Liliom'!$H10) -> 0
A11: =IF(COUNTA(Stats!E26)=1,Stats!E26,"") -> Multilayer | B11: =COUNTIFS('old -- All injections Dobos'!$C$2:$C$3002,'Summary Liliom'!$A11,'old -- All injections Dobos'!$B$2:$B$3002,'Summary Liliom'!B$3) -> 5 | C11: =COUNTIFS('old -- All injections Dobos'!$C$2:$C$3002,'Summary Liliom'!$A11,'old -- All injections Dobos'!$B$2:$B$3002,'Summary Liliom'!C$3) -> 0 | D11: =COUNTIFS('old -- All injections Dobos'!$C$2:$C$3002,'Summary Liliom'!$A11,'old -- All injections Dobos'!$B$2:$B$3002,'Summary Liliom'!D$3) -> 0 | E11: =COUNTIFS('old -- All injections Dobos'!$C$2:$C$3002,'Summary Liliom'!$A11,'old -- All injections Dobos'!$B$2:$B$3002,'Summary Liliom'!E$3) -> 0 | F11: =SUM(C11:E11) -> 0 | H11: =IF(COUNTA(Stats!G11)=1,Stats!G11,"") -> TG82 | I11: =COUNTIFS('old -- All injections Dobos'!J$2:J$3002,'Summary Liliom'!$H11) -> 3
A12: =IF(COUNTA(Stats!E27)=1,Stats!E27,"") -> Photostim | B12: =COUNTIFS('old -- All injections Dobos'!$C$2:$C$3002,'Summary Liliom'!$A12,'old -- All injections Dobos'!$B$2:$B$3002,'Summary Liliom'!B$3) -> 602 | C12: =COUNTIFS('old -- All injections Dobos'!$C$2:$C$3002,'Summary Liliom'!$A12,'old -- All injections Dobos'!$B$2:$B$3002,'Summary Liliom'!C$3) -> 0 | D12: =COUNTIFS('old -- All injections Dobos'!$C$2:$C$3002,'Summary Liliom'!$A12,'old -- All injections Dobos'!$B$2:$B$3002,'Summary Liliom'!D$3) -> 0 | E12: =COUNTIFS('old -- All injections Dobos'!$C$2:$C$3002,'Summary Liliom'!$A12,'old -- All injections Dobos'!$B$2:$B$3002,'Summary Liliom'!E$3) -> 0 | F12: =SUM(C12:E12) -> 0 | H12: =IF(COUNTA(Stats!G12)=1,Stats!G12,"") -> Thy1-Cre | I12: =COUNTIFS('old -- All injections Dobos'!J$2:J$3002,'Summary Liliom'!$H12) -> 936
A13: =IF(COUNTA(Stats!E28)=1,Stats!E28,"") -> Spectral demixing | B13: =COUNTIFS('old -- All injections Dobos'!$C$2:$C$3002,'Summary Liliom'!$A13,'old -- All injections Dobos'!$B$2:$B$3002,'Summary Liliom'!B$3) -> 3 | C13: =COUNTIFS('old -- All injections Dobos'!$C$2:$C$3002,'Summary Liliom'!$A13,'old -- All injections Dobos'!$B$2:$B$3002,'Summary Liliom'!C$3) -> 0 | D13: =COUNTIFS('old -- All injections Dobos'!$C$2:$C$3002,'Summary Liliom'!$A13,'old -- All injections Dobos'!$B$2:$B$3002,'Summary Liliom'!D$3) -> 0 | E13: =COUNTIFS('old -- All injections Dobos'!$C$2:$C$3002,'Summary Liliom'!$A13,'old -- All injections Dobos'!$B$2:$B$3002,'Summary Liliom'!E$3) -> 0 | F13: =SUM(C13:E13) -> 0 | H13: =IF(COUNTA(Stats!G13)=1,Stats!G13,"") -> VIP-cre | I13: =COUNTIFS('old -- All injections Dobos'!J$2:J$3002,'Summary Liliom'!$H13) -> 26
A14: =IF(COUNTA(Stats!E29)=1,Stats!E29,"") -> Treadmill | B14: =COUNTIFS('old -- All injections Dobos'!$C$2:$C$3002,'Summary Liliom'!$A14,'old -- All injections Dobos'!$B$2:$B$3002,'Summary Liliom'!B$3) -> 2 | C14: =COUNTIFS('old -- All injections Dobos'!$C$2:$C$3002,'Summary Liliom'!$A14,'old -- All injections Dobos'!$B$2:$B$3002,'Summary Liliom'!C$3) -> 0 | D14: =COUNTIFS('old -- All injections Dobos'!$C$2:$C$3002,'Summary Liliom'!$A14,'old -- All injections Dobos'!$B$2:$B$3002,'Summary Liliom'!D$3) -> 0 | E14: =COUNTIFS('old -- All injections Dobos'!$C$2:$C$3002,'Summary Liliom'!$A14,'old -- All injections Dobos'!$B$2:$B$3002,'Summary Liliom'!E$3) -> 0 | F14: =SUM(C14:E14) -> 0 | H14: =IF(COUNTA(Stats!G14)=1,Stats!G14,"") -> Rbp4-Cre | I14: =COUNTIFS('old -- All injections Dobos'!J$2:J$3002,'Summary Liliom'!$H14) -> 19
A15: =IF(COUNTA(Stats!E30)=1,Stats!E30,"") -> Uncage | B15: =COUNTIFS('old -- All injections Dobos'!$C$2:$C$3002,'Summary Liliom'!$A15,'old -- All injections Dobos'!$B$2:$B$3002,'Summary Liliom'!B$3) -> 8 | C15: =COUNTIFS('old -- All injections Dobos'!$C$2:$C$3002,'Summary Liliom'!$A15,'old -- All injections Dobos'!$B$2:$B$3002,'Summary Liliom'!C$3) -> 0 | D15: =COUNTIFS('old -- All injections Dobos'!$C$2:$C$3002,'Summary Liliom'!$A15,'old -- All injections Dobos'!$B$2:$B$3002,'Summary Liliom'!D$3) -> 0 | E15: =COUNTIFS('old -- All injections Dobos'!$C$2:$C$3002,'Summary Liliom'!$A15,'old -- All injections Dobos'!$B$2:$B$3002,'Summary Liliom'!E$3) -> 0 | F15: =SUM(C15:E15) -> 0 | H15: =IF(COUNTA(Stats!G15)=1,Stats!G15,"") -> BAC_Scnn1a/cre(Tg3Aibs)
A16: =IF(COUNTA(Stats!E31)=1,Stats!E31,"") -> Vírus teszt | B16: =COUNTIFS('old -- All injections Dobos'!$C$2:$C$3002,'Summary Liliom'!$A16,'old -- All injections Dobos'!$B$2:$B$3002,'Summary Liliom'!B$3) -> 6 | C16: =COUNTIFS('old -- All injections Dobos'!$C$2:$C$3002,'Summary Liliom'!$A16,'old -- All injections Dobos'!$B$2:$B$3002,'Summary Liliom'!C$3) -> 0 | D16: =COUNTIFS('old -- All injections Dobos'!$C$2:$C$3002,'Summary Liliom'!$A16,'old -- All injections Dobos'!$B$2:$B$3002,'Summary Liliom'!D$3) -> 0 | E16: =COUNTIFS('old -- All injections Dobos'!$C$2:$C$3002,'Summary Liliom'!$A16,'old -- All injections Dobos'!$B$2:$B$3002,'Summary Liliom'!E$3) -> 0 | F16: =SUM(C16:E16) -> 0 | H16: SUM | I16: =SUM(I4:I14) -> 1006
A17: =IF(COUNTA(Stats!E32)=1,Stats!E32,"") -> VSD | B17: =COUNTIFS('old -- All injections Dobos'!$C$2:$C$3002,'Summary Liliom'!$A17,'old -- All injections Dobos'!$B$2:$B$3002,'Summary Liliom'!B$3) -> 140 | C17: =COUNTIFS('old -- All injections Dobos'!$C$2:$C$3002,'Summary Liliom'!$A17,'old -- All injections Dobos'!$B$2:$B$3002,'Summary Liliom'!C$3) -> 0 | D17: =COUNTIFS('old -- All injections Dobos'!$C$2:$C$3002,'Summary Liliom'!$A17,'old -- All injections Dobos'!$B$2:$B$3002,'Summary Liliom'!D$3) -> 0 | E17: =COUNTIFS('old -- All injections Dobos'!$C$2:$C$3002,'Summary Liliom'!$A17,'old -- All injections Dobos'!$B$2:$B$3002,'Summary Liliom'!E$3) -> 0 | F17: =SUM(C17:E17) -> 0
A18: =IF(COUNTA(Stats!E33)=1,Stats!E33,"") -> VIP | B18: =COUNTIFS('old -- All injections Dobos'!$C$2:$C$3002,'Summary Liliom'!$A18,'old -- All injections Dobos'!$B$2:$B$3002,'Summary Liliom'!B$3) -> 108 | C18: =COUNTIFS('old -- All injections Dobos'!$C$2:$C$3002,'Summary Liliom'!$A18,'old -- All injections Dobos'!$B$2:$B$3002,'Summary Liliom'!C$3) -> 0 | D18: =COUNTIFS('old -- All injections Dobos'!$C$2:$C$3002,'Summary Liliom'!$A18,'old -- All injections Dobos'!$B$2:$B$3002,'Summary Liliom'!D$3) -> 0 | E18: =COUNTIFS('old -- All injections Dobos'!$C$2:$C$3002,'Summary Liliom'!$A18,'old -- All injections Dobos'!$B$2:$B$3002,'Summary Liliom'!E$3) -> 0 | F18: =SUM(C18:E18) -> 0
B19: =COUNTIFS('old -- All injections Dobos'!$C$2:$C$3002,'Summary Liliom'!$A19,'old -- All injections Dobos'!$B$2:$B$3002,'Summary Liliom'!B$3) -> 0 | C19: =COUNTIFS('old -- All injections Dobos'!$C$2:$C$3002,'Summary Liliom'!$A19,'old -- All injections Dobos'!$B$2:$B$3002,'Summary Liliom'!C$3) -> 0 | D19: =COUNTIFS('old -- All injections Dobos'!$C$2:$C$3002,'Summary Liliom'!$A19,'old -- All injections Dobos'!$B$2:$B$3002,'Summary Liliom'!D$3) -> 0 | E19: =COUNTIFS('old -- All injections Dobos'!$C$2:$C$3002,'Summary Liliom'!$A19,'old -- All injections Dobos'!$B$2:$B$3002,'Summary Liliom'!E$3) -> 0 | F19: =SUM(C19:E19) -> 0
B20: =COUNTIFS('old -- All injections Dobos'!$C$2:$C$3002,'Summary Liliom'!$A20,'old -- All injections Dobos'!$B$2:$B$3002,'Summary Liliom'!B$3) -> 0 | C20: =COUNTIFS('old -- All injections Dobos'!$C$2:$C$3002,'Summary Liliom'!$A20,'old -- All injections Dobos'!$B$2:$B$3002,'Summary Liliom'!C$3) -> 0 | D20: =COUNTIFS('old -- All injections Dobos'!$C$2:$C$3002,'Summary Liliom'!$A20,'old -- All injections Dobos'!$B$2:$B$3002,'Summary Liliom'!D$3) -> 0 | E20: =COUNTIFS('old -- All injections Dobos'!$C$2:$C$3002,'Summary Liliom'!$A20,'old -- All injections Dobos'!$B$2:$B$3002,'Summary Liliom'!E$3) -> 0 | F20: =SUM(C20:E20) -> 0
A21: SUM | B21: =SUM(B4:B20) -> 1374 | C21: =SUM(C4:C20) -> 0 | D21: =SUM(D4:D20) -> 0 | E21: =SUM(E4:E20) -> 0 | F21: =SUM(F4:F20) -> 0
A22: =IF(COUNTA(Stats!E43)=1,Stats!E43,"")

Sheet Help
A1: Online help document | D1: Mouse ID and virus injection table user manual

Sheet old -- Summary Dobos
A1: All animals stats | H1: Usage by line
A2: Project | B2: State | F2: Alive
B3: Death | C3: Injected | D3: Check-up | E3: Experiment | H3: Line | I3: Animals
B4: =COUNTIFS('old -- All injections Dobos'!$C$2:$C$3002,'old -- Summary Dobos'!$A4,'old -- All injections Dobos'!$B$2:$B$3002,'old -- Summary Dobos'!B$3) -> 0 | C4: =COUNTIFS('old -- All injections Dobos'!$C$2:$C$3002,'old -- Summary Dobos'!$A4,'old -- All injections Dobos'!$B$2:$B$3002,'old -- Summary Dobos'!C$3) -> 0 | D4: =COUNTIFS('old -- All injections Dobos'!$C$2:$C$3002,'old -- Summary Dobos'!$A4,'old -- All injections Dobos'!$B$2:$B$3002,'old -- Summary Dobos'!D$3) -> 0 | E4: =COUNTIFS('old -- All injections Dobos'!$C$2:$C$3002,'old -- Summary Dobos'!$A4,'old -- All injections Dobos'!$B$2:$B$3002,'old -- Summary Dobos'!E$3) -> 0 | F4: =SUM(C4:E4) -> 0 | H4: =IF(COUNTA(Stats!G4)=1,Stats!G4,"") -> BAC-pva/gfp | I4: =COUNTIFS('old -- All injections Dobos'!J$2:J$3002,'old -- Summary Dobos'!$H4) -> 10
A5: =IF(COUNTA(Stats!E20)=1,Stats!E20,"") -> ASO | B5: =COUNTIFS('old -- All injections Dobos'!$C$2:$C$3002,'old -- Summary Dobos'!$A5,'old -- All injections Dobos'!$B$2:$B$3002,'old -- Summary Dobos'!B$3) -> 86 | C5: =COUNTIFS('old -- All injections Dobos'!$C$2:$C$3002,'old -- Summary Dobos'!$A5,'old -- All injections Dobos'!$B$2:$B$3002,'old -- Summary Dobos'!C$3) -> 0 | D5: =COUNTIFS('old -- All injections Dobos'!$C$2:$C$3002,'old -- Summary Dobos'!$A5,'old -- All injections Dobos'!$B$2:$B$3002,'old -- Summary Dobos'!D$3) -> 0 | E5: =COUNTIFS('old -- All injections Dobos'!$C$2:$C$3002,'old -- Summary Dobos'!$A5,'old -- All injections Dobos'!$B$2:$B$3002,'old -- Summary Dobos'!E$3) -> 0 | F5: =SUM(C5:E5) -> 0 | H5: =IF(COUNTA(Stats!G5)=1,Stats!G5,"") -> C57Bl/6J | I5: =COUNTIFS('old -- All injections Dobos'!J$2:J$3002,'old -- Summary Dobos'!$H5) -> 0
A6: =IF(COUNTA(Stats!E21)=1,Stats!E21,"") -> Collaboration | B6: =COUNTIFS('old -- All injections Dobos'!$C$2:$C$3002,'old -- Summary Dobos'!$A6,'old -- All injections Dobos'!$B$2:$B$3002,'old -- Summary Dobos'!B$3) -> 39 | C6: =COUNTIFS('old -- All injections Dobos'!$C$2:$C$3002,'old -- Summary Dobos'!$A6,'old -- All injections Dobos'!$B$2:$B$3002,'old -- Summary Dobos'!C$3) -> 0 | D6: =COUNTIFS('old -- All injections Dobos'!$C$2:$C$3002,'old -- Summary Dobos'!$A6,'old -- All injections Dobos'!$B$2:$B$3002,'old -- Summary Dobos'!D$3) -> 0 | E6: =COUNTIFS('old -- All injections Dobos'!$C$2:$C$3002,'old -- Summary Dobos'!$A6,'old -- All injections Dobos'!$B$2:$B$3002,'old -- Summary Dobos'!E$3) -> 0 | F6: =SUM(C6:E6) -> 0 | H6: =IF(COUNTA(Stats!G6)=1,Stats!G6,"") -> C57Bl6/NTac | I6: =COUNTIFS('old -- All injections Dobos'!J$2:J$3002,'old -- Summary Dobos'!$H6) -> 0
A7: =IF(COUNTA(Stats!E22)=1,Stats!E22,"") -> Columna | B7: =COUNTIFS('old -- All injections Dobos'!$C$2:$C$3002,'old -- Summary Dobos'!$A7,'old -- All injections Dobos'!$B$2:$B$3002,'old -- Summary Dobos'!B$3) -> 222 | C7: =COUNTIFS('old -- All injections Dobos'!$C$2:$C$3002,'old -- Summary Dobos'!$A7,'old -- All injections Dobos'!$B$2:$B$3002,'old -- Summary Dobos'!C$3) -> 0 | D7: =COUNTIFS('old -- All injections Dobos'!$C$2:$C$3002,'old -- Summary Dobos'!$A7,'old -- All injections Dobos'!$B$2:$B$3002,'old -- Summary Dobos'!D$3) -> 0 | E7: =COUNTIFS('old -- All injections Dobos'!$C$2:$C$3002,'old -- Summary Dobos'!$A7,'old -- All injections Dobos'!$B$2:$B$3002,'old -- Summary Dobos'!E$3) -> 0 | F7: =SUM(C7:E7) -> 0 | H7: =IF(COUNTA(Stats!G7)=1,Stats!G7,"") -> FVB/Ant | I7: =COUNTIFS('old -- All injections Dobos'!J$2:J$3002,'old -- Summary Dobos'!$H7) -> 9
A8: =IF(COUNTA(Stats!E23)=1,Stats!E23,"") -> MS23 | B8: =COUNTIFS('old -- All injections Dobos'!$C$2:$C$3002,'old -- Summary Dobos'!$A8,'old -- All injections Dobos'!$B$2:$B$3002,'old -- Summary Dobos'!B$3) -> 80 | C8: =COUNTIFS('old -- All injections Dobos'!$C$2:$C$3002,'old -- Summary Dobos'!$A8,'old -- All injections Dobos'!$B$2:$B$3002,'old -- Summary Dobos'!C$3) -> 0 | D8: =COUNTIFS('old -- All injections Dobos'!$C$2:$C$3002,'old -- Summary Dobos'!$A8,'old -- All injections Dobos'!$B$2:$B$3002,'old -- Summary Dobos'!D$3) -> 0 | E8: =COUNTIFS('old -- All injections Dobos'!$C$2:$C$3002,'old -- Summary Dobos'!$A8,'old -- All injections Dobos'!$B$2:$B$3002,'old -- Summary Dobos'!E$3) -> 0 | F8: =SUM(C8:E8) -> 0 | H8: =IF(COUNTA(Stats!G8)=1,Stats!G8,"") -> PV-FLP | I8: =COUNTIFS('old -- All injections Dobos'!J$2:J$3002,'old -- Summary Dobos'!$H8) -> 3
A9: =IF(COUNTA(Stats!E24)=1,Stats!E24,"") -> MS71 | B9: =COUNTIFS('old -- All injections Dobos'!$C$2:$C$3002,'old -- Summary Dobos'!$A9,'old -- All injections Dobos'!$B$2:$B$3002,'old -- Summary Dobos'!B$3) -> 5 | C9: =COUNTIFS('old -- All injections Dobos'!$C$2:$C$3002,'old -- Summary Dobos'!$A9,'old -- All injections Dobos'!$B$2:$B$3002,'old -- Summary Dobos'!C$3) -> 0 | D9: =COUNTIFS('old -- All injections Dobos'!$C$2:$C$3002,'old -- Summary Dobos'!$A9,'old -- All injections Dobos'!$B$2:$B$3002,'old -- Summary Dobos'!D$3) -> 0 | E9: =COUNTIFS('old -- All injections Dobos'!$C$2:$C$3002,'old -- Summary Dobos'!$A9,'old -- All injections Dobos'!$B$2:$B$3002,'old -- Summary Dobos'!E$3) -> 0 | F9: =SUM(C9:E9) -> 0 | H9: =IF(COUNTA(Stats!G9)=1,Stats!G9,"") -> TG_GCaMP6s_DA | I9: =COUNTIFS('old -- All injections Dobos'!J$2:J$3002,'old -- Summary Dobos'!$H9) -> 0
A10: =IF(COUNTA(Stats!E25)=1,Stats!E25,"") -> Moculus | B10: =COUNTIFS('old -- All injections Dobos'!$C$2:$C$3002,'old -- Summary Dobos'!$A10,'old -- All injections Dobos'!$B$2:$B$3002,'old -- Summary Dobos'!B$3) -> 68 | C10: =COUNTIFS('old -- All injections Dobos'!$C$2:$C$3002,'old -- Summary Dobos'!$A10,'old -- All injections Dobos'!$B$2:$B$3002,'old -- Summary Dobos'!C$3) -> 0 | D10: =COUNTIFS('old -- All injections Dobos'!$C$2:$C$3002,'old -- Summary Dobos'!$A10,'old -- All injections Dobos'!$B$2:$B$3002,'old -- Summary Dobos'!D$3) -> 0 | E10: =COUNTIFS('old -- All injections Dobos'!$C$2:$C$3002,'old -- Summary Dobos'!$A10,'old -- All injections Dobos'!$B$2:$B$3002,'old -- Summary Dobos'!E$3) -> 0 | F10: =SUM(C10:E10) -> 0 | H10: =IF(COUNTA(Stats!G10)=1,Stats!G10,"") -> TG_GCaMP6F(82) | I10: =COUNTIFS('old -- All injections Dobos'!J$2:J$3002,'old -- Summary Dobos'!$H10) -> 0
A11: =IF(COUNTA(Stats!E26)=1,Stats!E26,"") -> Multilayer | B11: =COUNTIFS('old -- All injections Dobos'!$C$2:$C$3002,'old -- Summary Dobos'!$A11,'old -- All injections Dobos'!$B$2:$B$3002,'old -- Summary Dobos'!B$3) -> 5 | C11: =COUNTIFS('old -- All injections Dobos'!$C$2:$C$3002,'old -- Summary Dobos'!$A11,'old -- All injections Dobos'!$B$2:$B$3002,'old -- Summary Dobos'!C$3) -> 0 | D11: =COUNTIFS('old -- All injections Dobos'!$C$2:$C$3002,'old -- Summary Dobos'!$A11,'old -- All injections Dobos'!$B$2:$B$3002,'old -- Summary Dobos'!D$3) -> 0 | E11: =COUNTIFS('old -- All injections Dobos'!$C$2:$C$3002,'old -- Summary Dobos'!$A11,'old -- All injections Dobos'!$B$2:$B$3002,'old -- Summary Dobos'!E$3) -> 0 | F11: =SUM(C11:E11) -> 0 | H11: =IF(COUNTA(Stats!G11)=1,Stats!G11,"") -> TG82 | I11: =COUNTIFS('old -- All injections Dobos'!J$2:J$3002,'old -- Summary Dobos'!$H11) -> 3
A12: =IF(COUNTA(Stats!E27)=1,Stats!E27,"") -> Photostim | B12: =COUNTIFS('old -- All injections Dobos'!$C$2:$C$3002,'old -- Summary Dobos'!$A12,'old -- All injections Dobos'!$B$2:$B$3002,'old -- Summary Dobos'!B$3) -> 602 | C12: =COUNTIFS('old -- All injections Dobos'!$C$2:$C$3002,'old -- Summary Dobos'!$A12,'old -- All injections Dobos'!$B$2:$B$3002,'old -- Summary Dobos'!C$3) -> 0 | D12: =COUNTIFS('old -- All injections Dobos'!$C$2:$C$3002,'old -- Summary Dobos'!$A12,'old -- All injections Dobos'!$B$2:$B$3002,'old -- Summary Dobos'!D$3) -> 0 | E12: =COUNTIFS('old -- All injections Dobos'!$C$2:$C$3002,'old -- Summary Dobos'!$A12,'old -- All injections Dobos'!$B$2:$B$3002,'old -- Summary Dobos'!E$3) -> 0 | F12: =SUM(C12:E12) -> 0 | H12: =IF(COUNTA(Stats!G12)=1,Stats!G12,"") -> Thy1-Cre | I12: =COUNTIFS('old -- All injections Dobos'!J$2:J$3002,'old -- Summary Dobos'!$H12) -> 936
A13: =IF(COUNTA(Stats!E28)=1,Stats!E28,"") -> Spectral demixing | B13: =COUNTIFS('old -- All injections Dobos'!$C$2:$C$3002,'old -- Summary Dobos'!$A13,'old -- All injections Dobos'!$B$2:$B$3002,'old -- Summary Dobos'!B$3) -> 3 | C13: =COUNTIFS('old -- All injections Dobos'!$C$2:$C$3002,'old -- Summary Dobos'!$A13,'old -- All injections Dobos'!$B$2:$B$3002,'old -- Summary Dobos'!C$3) -> 0 | D13: =COUNTIFS('old -- All injections Dobos'!$C$2:$C$3002,'old -- Summary Dobos'!$A13,'old -- All injections Dobos'!$B$2:$B$3002,'old -- Summary Dobos'!D$3) -> 0 | E13: =COUNTIFS('old -- All injections Dobos'!$C$2:$C$3002,'old -- Summary Dobos'!$A13,'old -- All injections Dobos'!$B$2:$B$3002,'old -- Summary Dobos'!E$3) -> 0 | F13: =SUM(C13:E13) -> 0 | H13: =IF(COUNTA(Stats!G13)=1,Stats!G13,"") -> VIP-cre | I13: =COUNTIFS('old -- All injections Dobos'!J$2:J$3002,'old -- Summary Dobos'!$H13) -> 26
A14: =IF(COUNTA(Stats!E29)=1,Stats!E29,"") -> Treadmill | B14: =COUNTIFS('old -- All injections Dobos'!$C$2:$C$3002,'old -- Summary Dobos'!$A14,'old -- All injections Dobos'!$B$2:$B$3002,'old -- Summary Dobos'!B$3) -> 2 | C14: =COUNTIFS('old -- All injections Dobos'!$C$2:$C$3002,'old -- Summary Dobos'!$A14,'old -- All injections Dobos'!$B$2:$B$3002,'old -- Summary Dobos'!C$3) -> 0 | D14: =COUNTIFS('old -- All injections Dobos'!$C$2:$C$3002,'old -- Summary Dobos'!$A14,'old -- All injections Dobos'!$B$2:$B$3002,'old -- Summary Dobos'!D$3) -> 0 | E14: =COUNTIFS('old -- All injections Dobos'!$C$2:$C$3002,'old -- Summary Dobos'!$A14,'old -- All injections Dobos'!$B$2:$B$3002,'old -- Summary Dobos'!E$3) -> 0 | F14: =SUM(C14:E14) -> 0 | H14: =IF(COUNTA(Stats!G14)=1,Stats!G14,"") -> Rbp4-Cre | I14: =COUNTIFS('old -- All injections Dobos'!J$2:J$3002,'old -- Summary Dobos'!$H14) -> 19
A15: =IF(COUNTA(Stats!E30)=1,Stats!E30,"") -> Uncage | B15: =COUNTIFS('old -- All injections Dobos'!$C$2:$C$3002,'old -- Summary Dobos'!$A15,'old -- All injections Dobos'!$B$2:$B$3002,'old -- Summary Dobos'!B$3) -> 8 | C15: =COUNTIFS('old -- All injections Dobos'!$C$2:$C$3002,'old -- Summary Dobos'!$A15,'old -- All injections Dobos'!$B$2:$B$3002,'old -- Summary Dobos'!C$3) -> 0 | D15: =COUNTIFS('old -- All injections Dobos'!$C$2:$C$3002,'old -- Summary Dobos'!$A15,'old -- All injections Dobos'!$B$2:$B$3002,'old -- Summary Dobos'!D$3) -> 0 | E15: =COUNTIFS('old -- All injections Dobos'!$C$2:$C$3002,'old -- Summary Dobos'!$A15,'old -- All injections Dobos'!$B$2:$B$3002,'old -- Summary Dobos'!E$3) -> 0 | F15: =SUM(C15:E15) -> 0 | H15: =IF(COUNTA(Stats!G15)=1,Stats!G15,"") -> BAC_Scnn1a/cre(Tg3Aibs)
